Workbook

Sheet Excel_jumia_dataset (2)
A1: Product,Current price,old price,Discount,Review,Ratingd
A2: 115 Piece Set Of Multifunctional Precision Screwdrivers,KSh 950,"KSh 1,525",38%,-2,4.5 out of 5
A3: Metal Decorative Hooks Key Hangers Entryway Wall Hooks Towel Hooks - Home,KSh 527,KSh 999,47%,-14,4.1 out of 5
A4: Portable Mini Cordless Car Vacuum Cleaner - Blue,"KSh 2,199","KSh 2,923",25%,-24,4.6 out of 5
A5: Weighing Scale Digital Bathroom Body Fat Scale USB-Black,"KSh 1,580","KSh 2,499",37%,-7,4.7 out of 5
A6: Portable Home Small Air Humidifier 3-Speed Fan - Green,"KSh 1,740","KSh 2,356",26%,-5,4.8 out of 5
A7: 220V 60W Electric Soldering Iron Kits With Tools, Tips, And Multimeter,"KSh 2,999","KSh 3,290",9%,-15,4 out of 5
A8: 137 Pieces Cake Decorating Tool Set Baking Supplies,"KSh 2,319","KSh 3,032",24%,-55,4.6 out of 5
A9: Desk Foldable Fan Adjustable Fan Strong Wind 3 Gear Usb,KSh 988,"KSh 1,580",37%,-2,4 out of 5
A10: LASA FOLDING TABLE SERVING STAND,"KSh 1,274","KSh 2,800",55%,-5,4.8 out of 5
A11: 13 In 1 Home Repair Tools Box Kit Set,"KSh 1,600","KSh 2,929",45%,-5,3.8 out of 5
A12: Genebre 115 In 1 Screwdriver Repairing Tool Set For IPhone Cellphone Hand Tool,KSh 799,KSh 999,20%,-12,4.1 out of 5
... A116: Black Simple Water Cup Wine Coaster Anti Slip Absorbent,KSh 169,KSh 320,47%,,

Sheet Sheet1
A1: Product | B1: Current price | C1: old price | D1: Absolute Discount | E1: Discount | F1: Discount Category | G1: Review | H1: Ratings | I1: Rating Category | K1: AVERAGE
A2: 115 Piece Set Of Multifunctional Precision Screwdrivers | B2: 950 | C2: 1525 | D2: =C2-B2 -> 575 | E2: 0.38 | F2: =IF(E2<20%,"Low Discount",IF(E2<=40%,"Medium Discount","High Discount")) -> Medium Discount | G2: 2 | H2: 4.5 | I2: =IF(ISBLANK(H2),"Unknown",IF(H2<3,"Poor", IF(H2<=4,"Average", IF(H2<4.5,"Good","Excellent")))) -> Excellent | K2: Current Price | L2: =AVERAGE(B2:B113) -> 1186.8929
A3: Metal Decorative Hooks Key Hangers Entryway Wall Hooks Towel Hooks - Home | B3: 527 | C3: 999 | D3: =C3-B3 -> 472 | E3: 0.47 | F3: =IF(E3<20%,"Low Discount",IF(E3<=40%,"Medium Discount","High Discount")) -> High Discount | G3: 14 | H3: 4.1 | I3: =IF(ISBLANK(H3),"Unknown",IF(H3<3,"Poor", IF(H3<=4,"Average", IF(H3<4.5,"Good","Excellent")))) -> Good | K3: Old Price | L3: =AVERAGE(C2:C113) -> 1811.1071
A4: Portable Mini Cordless Car Vacuum Cleaner - Blue | B4: 2199 | C4: 2923 | D4: =C4-B4 -> 724 | E4: 0.25 | F4: =IF(E4<20%,"Low Discount",IF(E4<=40%,"Medium Discount","High Discount")) -> Medium Discount | G4: 24 | H4: 4.6 | I4: =IF(ISBLANK(H4),"Unknown",IF(H4<3,"Poor", IF(H4<=4,"Average", IF(H4<4.5,"Good","Excellent")))) -> Excellent | K4: Discount Percentage | L4: =AVERAGE(E2:E113) -> 0.36776786
A5: Weighing Scale Digital Bathroom Body Fat Scale USB-Black | B5: 1580 | C5: 2499 | D5: =C5-B5 -> 919 | E5: 0.37 | F5: =IF(E5<20%,"Low Discount",IF(E5<=40%,"Medium Discount","High Discount")) -> Medium Discount | G5: 7 | H5: 4.7 | I5: =IF(ISBLANK(H5),"Unknown",IF(H5<3,"Poor", IF(H5<=4,"Average", IF(H5<4.5,"Good","Excellent")))) -> Excellent | K5: Ratings | L5: =AVERAGE(H2:H113) -> 3.8894737
A6: Portable Home Small Air Humidifier 3-Speed Fan - Green | B6: 1740 | C6: 2356 | D6: =C6-B6 -> 616 | E6: 0.26 | F6: =IF(E6<20%,"Low Discount",IF(E6<=40%,"Medium Discount","High Discount")) -> Medium Discount | G6: 5 | H6: 4.8 | I6: =IF(ISBLANK(H6),"Unknown",IF(H6<3,"Poor", IF(H6<=4,"Average", IF(H6<4.5,"Good","Excellent")))) -> Excellent
A7: 220V 60W Electric Soldering Iron Kits With Tools, Tips, And Multimeter | B7: 2999 | C7: 3290 | D7: =C7-B7 -> 291 | E7: 0.09 | F7: =IF(E7<20%,"Low Discount",IF(E7<=40%,"Medium Discount","High Discount")) -> Low Discount | G7: 15 | H7: 4 | I7: =IF(ISBLANK(H7),"Unknown",IF(H7<3,"Poor", IF(H7<=4,"Average", IF(H7<4.5,"Good","Excellent")))) -> Average | K7: MEAN:
A8: 137 Pieces Cake Decorating Tool Set Baking Supplies | B8: 2319 | C8: 3032 | D8: =C8-B8 -> 713 | E8: 0.24 | F8: =IF(E8<20%,"Low Discount",IF(E8<=40%,"Medium Discount","High Discount")) -> Medium Discount | G8: 55 | H8: 4.6 | I8: =IF(ISBLANK(H8),"Unknown",IF(H8<3,"Poor", IF(H8<=4,"Average", IF(H8<4.5,"Good","Excellent")))) -> Excellent | K8: MAX | L8: =MAX(B2:B113) -> 3750
A9: Desk Foldable Fan Adjustable Fan Strong Wind 3 Gear Usb | B9: 988 | C9: 1580 | D9: =C9-B9 -> 592 | E9: 0.37 | F9: =IF(E9<20%,"Low Discount",IF(E9<=40%,"Medium Discount","High Discount")) -> Medium Discount | G9: 2 | H9: 4 | I9: =IF(ISBLANK(H9),"Unknown",IF(H9<3,"Poor", IF(H9<=4,"Average", IF(H9<4.5,"Good","Excellent")))) -> Average | K9: MIN | L9: =MIN(B2:B113) -> 38
A10: LASA FOLDING TABLE SERVING STAND | B10: 1274 | C10: 2800 | D10: =C10-B10 -> 1526 | E10: 0.55 | F10: =IF(E10<20%,"Low Discount",IF(E10<=40%,"Medium Discount","High Discount")) -> High Discount | G10: 5 | H10: 4.8 | I10: =IF(ISBLANK(H10),"Unknown",IF(H10<3,"Poor", IF(H10<=4,"Average", IF(H10<4.5,"Good","Excellent")))) -> Excellent
A11: 13 In 1 Home Repair Tools Box Kit Set | B11: 1600 | C11: 2929 | D11: =C11-B11 -> 1329 | E11: 0.45 | F11: =IF(E11<20%,"Low Discount",IF(E11<=40%,"Medium Discount","High Discount")) -> High Discount | G11: 5 | H11: 3.8 | I11: =IF(ISBLANK(H11),"Unknown",IF(H11<3,"Poor", IF(H11<=4,"Average", IF(H11<4.5,"Good","Excellent")))) -> Average
A12: Genebre 115 In 1 Screwdriver Repairing Tool Set For IPhone Cellphone Hand Tool | B12: 799 | C12: 999 | D12: =C12-B12 -> 200 | E12: 0.2 | F12: =IF(E12<20%,"Low Discount",IF(E12<=40%,"Medium Discount","High Discount")) -> Medium Discount | G12: 12 | H12: 4.1 | I12: =IF(ISBLANK(H12),"Unknown",IF(H12<3,"Poor", IF(H12<=4,"Average", IF(H12<4.5,"Good","Excellent")))) -> Good
A13: 100 Pcs Crochet Hook Tool Set Knitting Hook Set With Box | B13: 990 | C13: 1500 | D13: =C13-B13 -> 510 | E13: 0.34 | F13: =IF(E13<20%,"Low Discount",IF(E13<=40%,"Medium Discount","High Discount")) -> Medium Discount | G13: 39 | H13: 4.7 | I13: =IF(ISBLANK(H13),"Unknown",IF(H13<3,"Poor", IF(H13<=4,"Average", IF(H13<4.5,"Good","Excellent")))) -> Excellent
A14: 40cm Gold DIY Acrylic Wall Sticker Clock | B14: 552 | C14: 1035 | D14: =C14-B14 -> 483 | E14: 0.47 | F14: =IF(E14<20%,"Low Discount",IF(E14<=40%,"Medium Discount","High Discount")) -> High Discount | G14: 12 | H14: 4.8 | I14: =IF(ISBLANK(H14),"Unknown",IF(H14<3,"Poor", IF(H14<=4,"Average", IF(H14<4.5,"Good","Excellent")))) -> Excellent
A15: LASA Digital Thermometer And Hydrometer | B15: 501 | C15: 860 | D15: =C15-B15 -> 359 | E15: 0.42 | F15: =IF(E15<20%,"Low Discount",IF(E15<=40%,"Medium Discount","High Discount")) -> High Discount | G15: 6 | H15: 4.5 | I15: =IF(ISBLANK(H15),"Unknown",IF(H15<3,"Poor", IF(H15<=4,"Average", IF(H15<4.5,"Good","Excellent")))) -> Excellent
A16: Multifunction Laser Level With Adjustment Tripod | B16: 1680 | C16: 2499 | D16: =C16-B16 -> 819 | E16: 0.33 | F16: =IF(E16<20%,"Low Discount",IF(E16<=40%,"Medium Discount","High Discount")) -> Medium Discount | G16: 9 | H16: 4.2 | I16: =IF(ISBLANK(H16),"Unknown",IF(H16<3,"Poor", IF(H16<=4,"Average", IF(H16<4.5,"Good","Excellent")))) -> Good
A17: Anti-Skid Absorbent Insulation Coaster For Home Office | B17: 332 | C17: 684 | D17: =C17-B17 -> 352 | E17: 0.51 | F17: =IF(E17<20%,"Low Discount",IF(E17<=40%,"Medium Discount","High Discount")) -> High Discount | G17: 2 | H17: 5 | I17: =IF(ISBLANK(H17),"Unknown",IF(H17<3,"Poor", IF(H17<=4,"Average", IF(H17<4.5,"Good","Excellent")))) -> Excellent
A18: Peacock Throw Pillow Cushion Case For Home Car | B18: 195 | C18: 360 | D18: =C18-B18 -> 165 | E18: 0.46 | F18: =IF(E18<20%,"Low Discount",IF(E18<=40%,"Medium Discount","High Discount")) -> High Discount | G18: 2 | H18: 5 | I18: =IF(ISBLANK(H18),"Unknown",IF(H18<3,"Poor", IF(H18<=4,"Average", IF(H18<4.5,"Good","Excellent")))) -> Excellent
A19: LASA Aluminum Folding Truck Hand Cart - 68kg Max | B19: 2025 | C19: 3971 | D19: =C19-B19 -> 1946 | E19: 0.49 | F19: =IF(E19<20%,"Low Discount",IF(E19<=40%,"Medium Discount","High Discount")) -> High Discount | G19: 3 | H19: 5 | I19: =IF(ISBLANK(H19),"Unknown",IF(H19<3,"Poor", IF(H19<=4,"Average", IF(H19<4.5,"Good","Excellent")))) -> Excellent
A20: LED Wall Digital Alarm Clock Study Home 12 / 24H Clock Calendar | B20: 2999 | C20: 3699 | D20: =C20-B20 -> 700 | E20: 0.19 | F20: =IF(E20<20%,"Low Discount",IF(E20<=40%,"Medium Discount","High Discount")) -> Low Discount | G20: 5 | H20: 4.6 | I20: =IF(ISBLANK(H20),"Unknown",IF(H20<3,"Poor", IF(H20<=4,"Average", IF(H20<4.5,"Good","Excellent")))) -> Excellent
A21: 3D Waterproof EVA Plastic Shower Curtain 1.8*2Mtrs | B21: 998 | C21: 1966 | D21: =C21-B21 -> 968 | E21: 0.49 | F21: =IF(E21<20%,"Low Discount",IF(E21<=40%,"Medium Discount","High Discount")) -> High Discount | G21: 44 | H21: 4.6 | I21: =IF(ISBLANK(H21),"Unknown",IF(H21<3,"Poor", IF(H21<=4,"Average", IF(H21<4.5,"Good","Excellent")))) -> Excellent
A22: 3PCS Single Head Knitting Crochet Sweater Needle Set | B22: 38 | C22: 80 | D22: =C22-B22 -> 42 | E22: 0.53 | F22: =IF(E22<20%,"Low Discount",IF(E22<=40%,"Medium Discount","High Discount")) -> High Discount | G22: 13 | H22: 3.3 | I22: =IF(ISBLANK(H22),"Unknown",IF(H22<3,"Poor", IF(H22<=4,"Average", IF(H22<4.5,"Good","Excellent")))) -> Average
A23: 4pcs Bathroom/Kitchen Towel Rack,Roll Paper Holder,Towel Bars,Hook | B23: 1860 | C23: 3220 | D23: =C23-B23 -> 1360 | E23: 0.42 | F23: =IF(E23<20%,"Low Discount",IF(E23<=40%,"Medium Discount","High Discount")) -> High Discount | I23: =IF(ISBLANK(H23),"Unknown",IF(H23<3,"Poor", IF(H23<=4,"Average", IF(H23<4.5,"Good","Excellent")))) -> Unknown
A24: LED Romantic Spaceship Starry Sky Projector,Children's Bedroom Night Light-Blue | B24: 880 | C24: 1350 | D24: =C24-B24 -> 470 | E24: 0.35 | F24: =IF(E24<20%,"Low Discount",IF(E24<=40%,"Medium Discount","High Discount")) -> Medium Discount | G24: 6 | H24: 4 | I24: =IF(ISBLANK(H24),"Unknown",IF(H24<3,"Poor", IF(H24<=4,"Average", IF(H24<4.5,"Good","Excellent")))) -> Average
A25: Foldable Overbed Table/Desk | B25: 1650 | C25: 2150 | D25: =C25-B25 -> 500 | E25: 0.23 | F25: =IF(E25<20%,"Low Discount",IF(E25<=40%,"Medium Discount","High Discount")) -> Medium Discount | G25: 14 | H25: 4.4 | I25: =IF(ISBLANK(H25),"Unknown",IF(H25<3,"Poor", IF(H25<=4,"Average", IF(H25<4.5,"Good","Excellent")))) -> Good
A26: LASA 3 Tier Bamboo Shoe Bench Storage Shelf | B26: 2048 | C26: 4500 | D26: =C26-B26 -> 2452 | E26: 0.54 | F26: =IF(E26<20%,"Low Discount",IF(E26<=40%,"Medium Discount","High Discount")) -> High Discount | G26: 7 | H26: 4.3 | I26: =IF(ISBLANK(H26),"Unknown",IF(H26<3,"Poor", IF(H26<=4,"Average", IF(H26<4.5,"Good","Excellent")))) -> Good
A27: Electronic Digital Display Vernier Caliper | B27: 420 | C27: 647 | D27: =C27-B27 -> 227 | E27: 0.35 | F27: =IF(E27<20%,"Low Discount",IF(E27<=40%,"Medium Discount","High Discount")) -> Medium Discount | G27: 49 | H27: 4.6 | I27: =IF(ISBLANK(H27),"Unknown",IF(H27<3,"Poor", IF(H27<=4,"Average", IF(H27<4.5,"Good","Excellent")))) -> Excellent
A28: Portable Wardrobe Nonwoven With 3 Hanging Rods And 6 Storage Shelves | B28: 2880 | C28: 3520 | D28: =C28-B28 -> 640 | E28: 0.18 | F28: =IF(E28<20%,"Low Discount",IF(E28<=40%,"Medium Discount","High Discount")) -> Low Discount | G28: 12 | H28: 3.8 | I28: =IF(ISBLANK(H28),"Unknown",IF(H28<3,"Poor", IF(H28<=4,"Average", IF(H28<4.5,"Good","Excellent")))) -> Average
A29: 12 Litre Black Insulated Lunch Box | B29: 1350 | C29: 1990 | D29: =C29-B29 -> 640 | E29: 0.32 | F29: =IF(E29<20%,"Low Discount",IF(E29<=40%,"Medium Discount","High Discount")) -> Medium Discount | G29: 13 | H29: 3.8 | I29: =IF(ISBLANK(H29),"Unknown",IF(H29<3,"Poor", IF(H29<=4,"Average", IF(H29<4.5,"Good","Excellent")))) -> Average
A30: 52 Pieces Cake Decorating Tool Set Gift Kit Baking Supplies | B30: 1758 | C30: 2499 | D30: =C30-B30 -> 741 | E30: 0.3 | F30: =IF(E30<20%,"Low Discount",IF(E30<=40%,"Medium Discount","High Discount")) -> Medium Discount | G30: 20 | H30: 4.1 | I30: =IF(ISBLANK(H30),"Unknown",IF(H30<3,"Poor", IF(H30<=4,"Average", IF(H30<4.5,"Good","Excellent")))) -> Good
A31: MultiFunctional Storage Rack Multi-layer Bookshelf | B31: 2200 | C31: 4080 | D31: =C31-B31 -> 1880 | E31: 0.46 | F31: =IF(E31<20%,"Low Discount",IF(E31<=40%,"Medium Discount","High Discount")) -> High Discount | I31: =IF(ISBLANK(H31),"Unknown",IF(H31<3,"Poor", IF(H31<=4,"Average", IF(H31<4.5,"Good","Excellent")))) -> Unknown
A32: Exfoliate And Exfoliate Face Towel - Black | B32: 185 | C32: 382 | D32: =C32-B32 -> 197 | E32: 0.52 | F32: =IF(E32<20%,"Low Discount",IF(E32<=40%,"Medium Discount","High Discount")) -> High Discount | G32: 9 | H32: 4.3 | I32: =IF(ISBLANK(H32),"Unknown",IF(H32<3,"Poor", IF(H32<=4,"Average", IF(H32<4.5,"Good","Excellent")))) -> Good
A33: 12 Litre Insulated Lunch Box Grey | B33: 980 | C33: 1490 | D33: =C33-B33 -> 510 | E33: 0.34 | F33: =IF(E33<20%,"Low Discount",IF(E33<=40%,"Medium Discount","High Discount")) -> Medium Discount | G33: 12 | H33: 4.7 | I33: =IF(ISBLANK(H33),"Unknown",IF(H33<3,"Poor", IF(H33<=4,"Average", IF(H33<4.5,"Good","Excellent")))) -> Excellent
A34: LED Eye Protection Desk Lamp , Study, Reading, USB Fan - Double Pen Holder | B34: 1820 | C34: 3490 | D34: =C34-B34 -> 1670 | E34: 0.48 | F34: =IF(E34<20%,"Low Discount",IF(E34<=40%,"Medium Discount","High Discount")) -> High Discount | G34: 9 | H34: 4.3 | I34: =IF(ISBLANK(H34),"Unknown",IF(H34<3,"Poor", IF(H34<=4,"Average", IF(H34<4.5,"Good","Excellent")))) -> Good
A35: 53Pcs/Set Yarn Knitting Crochet Hooks With Bag - Fortune Cat | B35: 1940 | C35: 2650 | D35: =C35-B35 -> 710 | E35: 0.27 | F35: =IF(E35<20%,"Low Discount",IF(E35<=40%,"Medium Discount","High Discount")) -> Medium Discount | G35: 20 | H35: 4.7 | I35: =IF(ISBLANK(H35),"Unknown",IF(H35<3,"Poor", IF(H35<=4,"Average", IF(H35<4.5,"Good","Excellent")))) -> Excellent
A36: 53 Pieces/Set Yarn Knitting Crochet Hooks With Bag - Pansies | B36: 1980 | C36: 2699 | D36: =C36-B36 -> 719 | E36: 0.27 | F36: =IF(E36<20%,"Low Discount",IF(E36<=40%,"Medium Discount","High Discount")) -> Medium Discount | G36: 32 | H36: 4.5 | I36: =IF(ISBLANK(H36),"Unknown",IF(H36<3,"Poor", IF(H36<=4,"Average", IF(H36<4.5,"Good","Excellent")))) -> Excellent
A37: DIY File Folder, Office Drawer File Holder, Pen Holder, Desktop Storage Rack | B37: 1620 | C37: 2690 | D37: =C37-B37 -> 1070 | E37: 0.4 | F37: =IF(E37<20%,"Low Discount",IF(E37<=40%,"Medium Discount","High Discount")) -> Medium Discount | G37: 1 | H37: 5 | I37: =IF(ISBLANK(H37),"Unknown",IF(H37<3,"Poor", IF(H37<=4,"Average", IF(H37<4.5,"Good","Excellent")))) -> Excellent
A38: Classic Black Cat Cotton Hemp Pillow Case For Home Car | B38: 171 | C38: 360 | D38: =C38-B38 -> 189 | E38: 0.53 | F38: =IF(E38<20%,"Low Discount",IF(E38<=40%,"Medium Discount","High Discount")) -> High Discount | G38: 2 | H38: 5 | I38: =IF(ISBLANK(H38),"Unknown",IF(H38<3,"Poor", IF(H38<=4,"Average", IF(H38<4.5,"Good","Excellent")))) -> Excellent
A39: Punch-free Great Load Bearing Bathroom Storage Rack Wall Shelf-White | B39: 389 | C39: 656 | D39: =C39-B39 -> 267 | E39: 0.41 | F39: =IF(E39<20%,"Low Discount",IF(E39<=40%,"Medium Discount","High Discount")) -> High Discount | G39: 36 | H39: 4.3 | I39: =IF(ISBLANK(H39),"Unknown",IF(H39<3,"Poor", IF(H39<=4,"Average", IF(H39<4.5,"Good","Excellent")))) -> Good
A40: 1/2/3 Seater Elastic Sofa Cover,Living Room/Home Decor Chair Cover-Grey | B40: 1800 | C40: 2700 | D40: =C40-B40 -> 900 | E40: 0.38 | F40: =IF(E40<20%,"Low Discount",IF(E40<=40%,"Medium Discount","High Discount")) -> Medium Discount | G40: 2 | H40: 4.5 | I40: =IF(ISBLANK(H40),"Unknown",IF(H40<3,"Poor", IF(H40<=4,"Average", IF(H40<4.5,"Good","Excellent")))) -> Excellent
...

Sheet Sheet3
A1: DESCRIPTIVE STATISTICS
A2: Metric | B2: Value
A3: Total Products | B3: =COUNTA(Sheet1!A2:A113) -> 112
A4: Avg Current Price (KSh) | B4: =AVERAGE(Sheet1!B2:B113) -> 1186.8929
A5: Avg Old Price (KSh) | B5: =AVERAGE(Sheet1!C2:C113) -> 1811.1071
A6: Avg Discount % | B6: =AVERAGE(Sheet1!E2:E113) -> 0.36776786
A7: Avg Rating | B7: =AVERAGE(Sheet1!H2:H113) -> 3.8894737
A8: Total Reviews | B8: {=SUM(ABS(Sheet1!G2:G113))} -> 723
A9: Most Expensive Product | B9: 32PCS Portable Cordless Drill Set With Cyclic Battery Drive -26 Variable Speed
A10: Highest Price (KSh) | B10: =MAX(Sheet1!B2:B113) -> 3750
A11: Least Expensive Product | B11: 3PCS Single Head Knitting Crochet Sweater Needle Set
A12: Lowest Price (KSh) | B12: =MIN(Sheet1!B2:B113) -> 38
A13: Max Discount % | B13: =MAX(Sheet1!E2:E113) -> 0.64
A14: Min Discount % | B14: =MIN(Sheet1!E2:E113) -> 0.01
A18: RATING CATEGORY BREAKDOWN
A19: Rating Category | B19: Count | C19: Avg Price | D19: Avg Reviews
A20: Poor | B20: =COUNTIF(Sheet1!I2:I113,"Poor") -> 12 | C20: =IFERROR(AVERAGEIF(Sheet1!I2:I113,"Poor",Sheet1!B2:B113),"") -> 998.33333 | D20: =IFERROR(AVERAGEIF(Sheet1!I2:I113,"Poor",Sheet1!G2:G113),"") -> 14.083333
A21: Average | B21: =COUNTIF(Sheet1!I2:I113,"Average") -> 13 | C21: =IFERROR(AVERAGEIF(Sheet1!I2:I113,"Average",Sheet1!B2:B113),"") -> 1482.3846 | D21: =IFERROR(AVERAGEIF(Sheet1!I2:I113,"Average",Sheet1!G2:G113),"") -> 7.1538462
A22: Good | B22: =COUNTIF(Sheet1!I2:I113,"Good") -> 9 | C22: =IFERROR(AVERAGEIF(Sheet1!I2:I113,"Good",Sheet1!B2:B113),"") -> 1206.2222 | D22: =IFERROR(AVERAGEIF(Sheet1!I2:I113,"Good",Sheet1!G2:G113),"") -> 14.444444
A23: Excellent | B23: =COUNTIF(Sheet1!I2:I114,"Excellent") -> 23 | C23: =IFERROR(AVERAGEIF(Sheet1!I2:I113,"Excellent",Sheet1!B2:B113),"") -> 1399.3043 | D23: =IFERROR(AVERAGEIF(Sheet1!I2:I113,"Excellent",Sheet1!G2:G113),"") -> 14.391304
A24: Unknown | B24: =COUNTIF(Sheet1!I2:I113,"Unknown") -> 55 | C24: =IFERROR(AVERAGEIF(Sheet1!I2:I113,"Unknown",Sheet1!B2:B113),"") -> 1066.2 | D24: =IFERROR(AVERAGEIF(Sheet1!I2:I113,"Unknown",Sheet1!G2:G113),"")
A27: DISCOUNT CATEGORY BREAKDOWN
A28: Discount Category | B28: Count | C28: Avg Rating | D28: Avg Reviews
A29: Low Discount | B29: =COUNTIF(Sheet1!F2:F113,"Low Discount") -> 18 | C29: =IFERROR(AVERAGEIF(Sheet1!F2:F113,"Low Discount",Sheet1!H2:H113),"") -> 3.725 | D29: =IFERROR(AVERAGEIF(Sheet1!F2:F113,"Low Discount",Sheet1!G2:G113),"") -> 9.5
A30: Medium Discount | B30: =COUNTIF(Sheet1!F2:F113,"Medium Discount") -> 32 | C30: =IFERROR(AVERAGEIF(Sheet1!F2:F113,"Medium Discount",Sheet1!H2:H113),"") -> 4.2782609 | D30: =IFERROR(AVERAGEIF(Sheet1!F2:F113,"Medium Discount",Sheet1!G2:G113),"") -> 15.26087
A31: High Discount | B31: =COUNTIF(Sheet1!F2:F113,"High Discount") -> 62 | C31: =IFERROR(AVERAGEIF(Sheet1!F2:F113,"High Discount",Sheet1!H2:H113),"") -> 3.6133333 | D31: =IFERROR(AVERAGEIF(Sheet1!F2:F113,"High Discount",Sheet1!G2:G113),"") -> 11.133333

Sheet Trend Analysis
A1: A. Discount % Bucket vs Avg Reviews
A2: Discount % Range | B2: Avg Reviews | C2: Product Count
A3: 0% – 20% | B3: =IFERROR(AVERAGEIFS(Sheet1!G$2:G$113,Sheet1!E$2:E$113,">=0",Sheet1!E$2:E$113,"<=0.2"),0) -> 10 | C3: =COUNTIFS(Sheet1!E$2:E$113,">=0",Sheet1!E$2:E$113,"<=0.2") -> 19
A4: 21% – 40% | B4: =IFERROR(AVERAGEIFS(Sheet1!G$2:G$113,Sheet1!E$2:E$113,">=0.21",Sheet1!E$2:E$113,"<=0.4"),0) -> 15.409091 | C4: =COUNTIFS(Sheet1!E$2:E$113,">=0.21",Sheet1!E$2:E$113,"<=0.4") -> 31
A5: 41% – 60% | B5: =IFERROR(AVERAGEIFS(Sheet1!G$2:G$113,Sheet1!E$2:E$113,">=0.41",Sheet1!E$2:E$113,"<=0.6"),0) -> 11.133333 | C5: =COUNTIFS(Sheet1!E$2:E$113,">=0.41",Sheet1!E$2:E$113,"<=0.6") -> 60
A6: 61% – 80% | B6: =IFERROR(AVERAGEIFS(Sheet1!G$2:G$113,Sheet1!E$2:E$113,">=0.61",Sheet1!E$2:E$113,"<=0.8"),0) -> 0 | C6: =COUNTIFS(Sheet1!E$2:E$113,">=0.61",Sheet1!E$2:E$113,"<=0.8") -> 2
A7: >80% | B7: =IFERROR(AVERAGEIFS(Sheet1!G$2:G$113,Sheet1!E$2:E$113,">=0.81",Sheet1!E$2:E$113,"<=1.0"),0) -> 0 | C7: =COUNTIFS(Sheet1!E$2:E$113,">=0.81",Sheet1!E$2:E$113,"<=1.0") -> 0
A11: B. Rating Bucket vs Avg Reviews
A12: Rating Range | B12: Avg Reviews | C12: Product Count
A13: 2.0–2.9 (Poor) | B13: =IFERROR(AVERAGEIFS(Sheet1!G$2:G$113,Sheet1!H$2:H$113,">=2.0",Sheet1!H$2:H$113,"<=2.9"),0) -> 14.083333 | C13: =COUNTIFS(Sheet1!H$2:H$113,">=2.0",Sheet1!H$2:H$113,"<=2.9") -> 12
A14: 3.0–4.0 (Average) | B14: =IFERROR(AVERAGEIFS(Sheet1!G$2:G$113,Sheet1!H$2:H$113,">=3.0",Sheet1!H$2:H$113,"<=4.0"),0) -> 7.1538462 | C14: =COUNTIFS(Sheet1!H$2:H$113,">=3.0",Sheet1!H$2:H$113,"<=4.0") -> 13
A15: 4.1–4.4 (Good) | B15: =IFERROR(AVERAGEIFS(Sheet1!G$2:G$113,Sheet1!H$2:H$113,">=4.1",Sheet1!H$2:H$113,"<=4.4"),0) -> 14.444444 | C15: =COUNTIFS(Sheet1!H$2:H$113,">=4.1",Sheet1!H$2:H$113,"<=4.4") -> 9
A16: 4.5–5.0 (Excellent) | B16: =IFERROR(AVERAGEIFS(Sheet1!G$2:G$113,Sheet1!H$2:H$113,">=4.5",Sheet1!H$2:H$113,"<=5.0"),0) -> 14.391304 | C16: =COUNTIFS(Sheet1!H$2:H$113,">=4.5",Sheet1!H$2:H$113,"<=5.0") -> 23
A19: C. High Discount (≥40%) but Low Rating (≤3.5) Products
A20: Product | B20: Discount % | C20: Rating | D20: Reviews | E20: Disc. Category | F20: Rating Category
A21: 3PCS Single Head Knitting Crochet Sweater Needle Set | B21: 0.53 | C21: 3.3 | D21: 13 | E21: Medium Discount | F21: Average
A22: Mythco 120COB Solar Wall Ligt With Motion Sensor And Remote Control 3 Modes | B22: 0.54 | C22: 3 | D22: 10 | E22: Medium Discount | F22: Average
A23: 5-PCS Stainless Steel Cooking Pot Set With Steamed Slices | B23: 0.55 | C23: 2.1 | D23: 13 | E23: Medium Discount | F23: Poor
A24: 120W Cordless Vacuum Cleaners Handheld Electric Vacuum Cleaner | B24: 0.49 | C24: 2.8 | D24: 69 | E24: Medium Discount | F24: Poor
A25: Intelligent LED Body Sensor Wireless Lighting Night Light USB | B25: 0.52 | C25: 2.7 | D25: 15 | E25: Medium Discount | F25: Poor
A26: Artificial Potted Flowers Room Decorative Flowers (2 Pieces) | B26: 0.45 | C26: 2.2 | D26: 6 | E26: Medium Discount | F26: Poor
A27: 380ML USB Rechargeable Portable Small Blenders And Juicers | B27: 0.5 | C27: 2.3 | D27: 7 | E27: Medium Discount | F27: Poor
A28: Agapeon Toothbrush Holder And Toothpaste Dispenser | B28: 0.45 | C28: 2.6 | D28: 17 | E28: Medium Discount | F28: Poor
A29: Watercolour Gold Foil Textured Print Pillow Cover | B29: 0.43 | C29: 2.3 | D29: 6 | E29: Medium Discount | F29: Poor
A30: Wrought Iron Bathroom Shelf Wall Mounted Free Punch Toilet Rack | B30: 0.43 | C30: 3 | D30: 5 | E30: Medium Discount | F30: Average
A31: 7-piece Set Of Storage Bags, Travel Storage Bags, Shoe Bags | B31: 0.47 | C31: 2.2 | D31: 6 | E31: Medium Discount | F31: Poor
A32: Electric LED UV Mosquito Killer Lamp, Outdoor/Indoor Fly Killer Trap Light -USB | B32: 0.47 | C32: 2.1 | D32: 7 | E32: Medium Discount | F32: Poor
... A34: Wall-mounted Sticker Punch-free Plug Fixer | B34: 0.5 | C34: 2 | D34: 1 | E34: Medium Discount | F34: Poor
A37: E. TOP 5 HIGHEST-RATED PRODUCTS
A38: Rank | B38: Product Name | C38: Rating (/5)
A39: 1 | B39: =IFERROR(INDEX(Sheet1!A$2:A$113,MATCH(LARGE(Sheet1!H$2:H$113,1),Sheet1!H$2:H$113,0)),"") -> Anti-Skid Absorbent Insulation Coaster For Home Office | C39: =IFERROR(LARGE(Sheet1!H$2:H$113,1),"") -> 5
A40: 2 | B40: =IFERROR(INDEX(Sheet1!A$2:A$113,MATCH(LARGE(Sheet1!H$2:H$113,2),Sheet1!H$2:H$113,0)),"") -> Anti-Skid Absorbent Insulation Coaster For Home Office | C40: =IFERROR(LARGE(Sheet1!H$2:H$113,2),"") -> 5
A41: 3 | B41: =IFERROR(INDEX(Sheet1!A$2:A$113,MATCH(LARGE(Sheet1!H$2:H$113,3),Sheet1!H$2:H$113,0)),"") -> Anti-Skid Absorbent Insulation Coaster For Home Office | C41: =IFERROR(LARGE(Sheet1!H$2:H$113,3),"") -> 5
A42: 4 | B42: =IFERROR(INDEX(Sheet1!A$2:A$113,MATCH(LARGE(Sheet1!H$2:H$113,3),Sheet1!H$2:H$113,0)),"") -> Anti-Skid Absorbent Insulation Coaster For Home Office | C42: =IFERROR(LARGE(Sheet1!H$2:H$113,4),"") -> 5
A43: 5 | B43: =IFERROR(INDEX(Sheet1!A$2:A$113,MATCH(LARGE(Sheet1!H$2:H$113,5),Sheet1!H$2:H$113,0)),"") -> Anti-Skid Absorbent Insulation Coaster For Home Office | C43: =IFERROR(LARGE(Sheet1!H$2:H$113,5),"") -> 5
A46: F. TOP 5 LOWEST-RATED PRODUCTS
A47: Rank | B47: Product Name | C47: Rating (/5)
A48: 1 | B48: =IFERROR(INDEX(Sheet1!A$2:A$113,MATCH(SMALL(Sheet1!H$2:H$113,1),Sheet1!H$2:H$113,0)),"") -> Wall-mounted Sticker Punch-free Plug Fixer | C48: =IFERROR(SMALL(Sheet1!H$2:H$113,1),"") -> 2
A49: 2 | B49: =IFERROR(INDEX(Sheet1!A$2:A$113,MATCH(SMALL(Sheet1!H$2:H$113,2),Sheet1!H$2:H$113,0)),"") -> 5-PCS Stainless Steel Cooking Pot Set With Steamed Slices | C49: =IFERROR(SMALL(Sheet1!H$2:H$113,2),"") -> 2.1
A50: 3 | B50: =IFERROR(INDEX(Sheet1!A$2:A$113,MATCH(SMALL(Sheet1!H$2:H$113,3),Sheet1!H$2:H$113,0)),"") -> 5-PCS Stainless Steel Cooking Pot Set With Steamed Slices | C50: =IFERROR(SMALL(Sheet1!H$2:H$113,3),"") -> 2.1
...

Sheet Product Performance
A1: =[1]Analysis!F22 -> TOP 10 BY DISCOUNT
A2: =[1]Analysis!F23 -> Product (Top Discount) | B2: =[1]Analysis!G23 -> Discount %
A3: =IFERROR(INDEX(Sheet1!A$2:A$113,MATCH(LARGE(Sheet1!E$2:E$113,1),Sheet1!E$2:E$113,0)),"") -> 6 In 1 Bottle Can Opener Multifunctional Easy Opener | B3: =IFERROR(LARGE(Sheet1!E$2:E$113,1),"") -> 0.64
A4: =IFERROR(INDEX(Sheet1!A$2:A$113,MATCH(LARGE(Sheet1!E$2:E$113,2),Sheet1!E$2:E$113,0)),"") -> Creative Owl Shape Keychain Black | B4: =IFERROR(LARGE(Sheet1!E$2:E$113,2),"") -> 0.61
A5: =IFERROR(INDEX(Sheet1!A$2:A$113,MATCH(LARGE(Sheet1!E$2:E$113,3),Sheet1!E$2:E$113,0)),"") -> LASA FOLDING TABLE SERVING STAND | B5: =IFERROR(LARGE(Sheet1!E$2:E$113,3),"") -> 0.55
A6: =IFERROR(INDEX(Sheet1!A$2:A$113,MATCH(LARGE(Sheet1!E$2:E$113,4),Sheet1!E$2:E$113,0)),"") -> LASA FOLDING TABLE SERVING STAND | B6: =IFERROR(LARGE(Sheet1!E$2:E$113,4),"") -> 0.55
A7: =IFERROR(INDEX(Sheet1!A$2:A$113,MATCH(LARGE(Sheet1!E$2:E$113,5),Sheet1!E$2:E$113,0)),"") -> LASA FOLDING TABLE SERVING STAND | B7: =IFERROR(LARGE(Sheet1!E$2:E$113,5),"") -> 0.55
A8: =IFERROR(INDEX(Sheet1!A$2:A$113,MATCH(LARGE(Sheet1!E$2:E$113,6),Sheet1!E$2:E$113,0)),"") -> LASA 3 Tier Bamboo Shoe Bench Storage Shelf | B8: =IFERROR(LARGE(Sheet1!E$2:E$113,6),"") -> 0.54
A9: =IFERROR(INDEX(Sheet1!A$2:A$113,MATCH(LARGE(Sheet1!E$2:E$113,7),Sheet1!E$2:E$113,0)),"") -> LASA 3 Tier Bamboo Shoe Bench Storage Shelf | B9: =IFERROR(LARGE(Sheet1!E$2:E$113,7),"") -> 0.54
A10: =IFERROR(INDEX(Sheet1!A$2:A$113,MATCH(LARGE(Sheet1!E$2:E$113,8),Sheet1!E$2:E$113,0)),"") -> 3PCS Single Head Knitting Crochet Sweater Needle Set | B10: =IFERROR(LARGE(Sheet1!E$2:E$113,8),"") -> 0.53
A11: =IFERROR(INDEX(Sheet1!A$2:A$113,MATCH(LARGE(Sheet1!E$2:E$113,9),Sheet1!E$2:E$113,0)),"") -> 3PCS Single Head Knitting Crochet Sweater Needle Set | B11: =IFERROR(LARGE(Sheet1!E$2:E$113,9),"") -> 0.53
A12: =IFERROR(INDEX(Sheet1!A$2:A$113,MATCH(LARGE(Sheet1!E$2:E$113,10),Sheet1!E$2:E$113,0)),"") -> Exfoliate And Exfoliate Face Towel - Black | B12: =IFERROR(LARGE(Sheet1!E$2:E$113,10),"") -> 0.52
A14: TOP 10 BY REVIEWS
A15: Product (Most Reviews) | B15: Reviews
A16: =IFERROR(INDEX(Sheet1!A$2:A$113,MATCH(LARGE(Sheet1!G$2:G$113,1),Sheet1!G$2:G$113,0)),"") -> 120W Cordless Vacuum Cleaners Handheld Electric Vacuum Cleaner | B16: =IFERROR(ABS(LARGE(Sheet1!G$2:G$113,1)),"") -> 69
A17: =IFERROR(INDEX(Sheet1!A$2:A$113,MATCH(LARGE(Sheet1!G$2:G$113,2),Sheet1!G$2:G$113,0)),"") -> 137 Pieces Cake Decorating Tool Set Baking Supplies | B17: =IFERROR(ABS(LARGE(Sheet1!G$2:G$113,2)),"") -> 55
A18: =IFERROR(INDEX(Sheet1!A$2:A$113,MATCH(LARGE(Sheet1!G$2:G$113,3),Sheet1!G$2:G$113,0)),"") -> Electronic Digital Display Vernier Caliper | B18: =IFERROR(ABS(LARGE(Sheet1!G$2:G$113,3)),"") -> 49
A19: =IFERROR(INDEX(Sheet1!A$2:A$113,MATCH(LARGE(Sheet1!G$2:G$113,4),Sheet1!G$2:G$113,0)),"") -> 3D Waterproof EVA Plastic Shower Curtain 1.8*2Mtrs | B19: =IFERROR(ABS(LARGE(Sheet1!G$2:G$113,4)),"") -> 44
A20: =IFERROR(INDEX(Sheet1!A$2:A$113,MATCH(LARGE(Sheet1!G$2:G$113,5),Sheet1!G$2:G$113,0)),"") -> 100 Pcs Crochet Hook Tool Set Knitting Hook Set With Box | B20: =IFERROR(ABS(LARGE(Sheet1!G$2:G$113,5)),"") -> 39
A21: =IFERROR(INDEX(Sheet1!A$2:A$113,MATCH(LARGE(Sheet1!G$2:G$113,6),Sheet1!G$2:G$113,0)),"") -> Punch-free Great Load Bearing Bathroom Storage Rack Wall Shelf-White | B21: =IFERROR(ABS(LARGE(Sheet1!G$2:G$113,6)),"") -> 36
A22: =IFERROR(INDEX(Sheet1!A$2:A$113,MATCH(LARGE(Sheet1!G$2:G$113,7),Sheet1!G$2:G$113,0)),"") -> 53 Pieces/Set Yarn Knitting Crochet Hooks With Bag - Pansies | B22: =IFERROR(ABS(LARGE(Sheet1!G$2:G$113,7)),"") -> 32
A23: =IFERROR(INDEX(Sheet1!A$2:A$113,MATCH(LARGE(Sheet1!G$2:G$113,8),Sheet1!G$2:G$113,0)),"") -> Portable Mini Cordless Car Vacuum Cleaner - Blue | B23: =IFERROR(ABS(LARGE(Sheet1!G$2:G$113,8)),"") -> 24
A24: =IFERROR(INDEX(Sheet1!A$2:A$113,MATCH(LARGE(Sheet1!G$2:G$113,9),Sheet1!G$2:G$113,0)),"") -> 52 Pieces Cake Decorating Tool Set Gift Kit Baking Supplies | B24: =IFERROR(ABS(LARGE(Sheet1!G$2:G$113,9)),"") -> 20
A25: =IFERROR(INDEX(Sheet1!A$2:A$113,MATCH(LARGE(Sheet1!G$2:G$113,10),Sheet1!G$2:G$113,0)),"") -> 52 Pieces Cake Decorating Tool Set Gift Kit Baking Supplies | B25: =IFERROR(ABS(LARGE(Sheet1!G$2:G$113,10)),"") -> 20

Sheet Dashboard
A1: JUMIA PRODUCT PERFORMANCE DASHBOARD
A2: SECTION 1 — OVERVIEW: KEY METRICS
B4: =Sheet3!B3 -> 112 | H4: =Sheet3!B8 -> 723 | N4: =Sheet3!B7 -> 3.8894737 | S4: =Sheet3!B6 -> 0.36776786
B5: Total Products | H5: Total Reviews | N5: Avg Rating (/5) | S5: Avg Discount %
A8: SECTION 3 - PRODUCT CATEGORIES
